## 解决日志没有换行的问题

### 一、背景：
该服务用的是oslo_log来管理日志，并且对接了rsyslog，有一次在查看日志的时候，发现异常日志都是单行显示的，非常不利于查看
```sh
2019-11-14 17:49:13.774 -proxy [_proxy] crit CRITICAL _proxy [pid:57012] [MainThread] [log.py:193 logging_excepthook]  Unhandled error: error: [Errno 98] Address already in use#012TRACE _proxy Traceback (most recent call last):#012TRACE _proxy   File "/usr/bin/_proxy", line 10, in <module>#012TRACE _proxy     sys.exit(main())#012TRACE _proxy   File "/usr/lib/python2.7/site-packages/_proxy/launcher.py", line 25, in main#012TRACE _proxy     server = service.Service("_proxy")#012TRACE _proxy   File "/usr/lib/python2.7/site-packages/_proxy/wsgi/service.py", line 48, in __init__#012TRACE _proxy     use_ssl=use_ssl)#012TRACE _proxy   File "/usr/lib/python2.7/site-packages/oslo_service/wsgi.py", line 115, in __init__#012TRACE _proxy     self.socket = self._get_socket(host, port, backlog)#012TRACE _proxy   File "/usr/lib/python2.7/site-packages/oslo_service/wsgi.py", line 143, in _get_socket#012TRACE _proxy     sock = eventlet.listen(bind_addr, family, backlog=backlog)#012TRACE _proxy   File "/usr/lib/python2.7/site-packages/eventlet/convenience.py", line 47, in listen#012TRACE _proxy     sock.listen(backlog)#012TRACE _proxy   File "/usr/lib/python2.7/socket.py", line 228, in meth#012TRACE _proxy     return getattr(self._sock,name)(*args)#012TRACE _proxy error: [Errno 98] Address already in use#012TRACE _proxy
```

### 二、排查：
通过观察该日志，发现其实是多行的，只是\n被转义成了#012字符

#### 1、刚开始以为是oslo_log的问题

以为需要配置什么参数才行，该服务当前的配置如下：

```sh
use_syslog = True
syslog_log_facility = local1
logging_context_format_string  = %(levelname)s %(name)s [pid:%(process)d] [%(threadName)s] [%(filename)s:%(lineno)d %(funcName)s] [%(request_id)s] %(instance)s %(message)s
logging_debug_format_suffix    = %(levelname)s %(name)s [pid:%(process)d] [%(threadName)s] [%(filename)s:%(lineno)d %(funcName)s] %(instance)s %(message)s
logging_default_format_string  = %(levelname)s %(name)s [pid:%(process)d] [%(threadName)s] [%(filename)s:%(lineno)d %(funcName)s] %(instance)s %(message)s
logging_exception_prefix       = TRACE %(name)s %(instance)s
```
但是查看了oslo_log官方的所有配置参数，发现没有关于这方面的设置。

#### 2、然后联想到oslog_log使用了rsyslog

日志文件中的日志都是通过rsyslog写入的，那会不会是rsyslog的问题呢？该服务当前的配置如下：

```sh
$FileOwner xx
$FileGroup xx
$FileCreateMode 0740
$Umask 0027

$template logFormat,"%timegenerated:1:10:date-rfc3339% %timegenerated:12:23:date-rfc3339% %hostname% [%programname%] %syslogseverity-text% %msg%\n"

$template controlLogFormat,"%timegenerated:1:10:date-rfc3339% %timegenerated:12:23:date-rfc3339% %hostname% [%programname%] %syslogseverity-text% %msg%\n"

if $programname == 'xx' then
{
    local1.info xx/xx.log;logFormat
    local1.* ~
}

if $programname == 'xx' then
{
    local1.info xx/xx.log;controlLogFormat
    local1.* ~
}
```
通过google + stackoverflow 果然找到了相同的问题，需要在rsyslog的配置中加上如下一个参数：
```sh
$EscapeControlCharactersOnReceive off
```
然后重启service rsyslog restart
果然解决了问题，日志显示如下：
```sh
2019-11-14 19:06:23.511 -proxy [_proxy] crit CRITICAL _proxy [pid:9224] [MainThread] [log.py:193 logging_excepthook]  Unhandled error: error: [Errno 98] Address already in use
TRACE _proxy Traceback (most recent call last):
TRACE _proxy   File "/usr/bin/_proxy", line 10, in <module>
TRACE _proxy     sys.exit(main())
TRACE _proxy   File "/usr/lib/python2.7/site-packages/_proxy/launcher.py", line 25, in main
TRACE _proxy     server = service.Service("_proxy")
TRACE _proxy   File "/usr/lib/python2.7/site-packages/_proxy/wsgi/service.py", line 48, in __init__
TRACE _proxy     use_ssl=use_ssl)
TRACE _proxy   File "/usr/lib/python2.7/site-packages/oslo_service/wsgi.py", line 115, in __init__
TRACE _proxy     self.socket = self._get_socket(host, port, backlog)
TRACE _proxy   File "/usr/lib/python2.7/site-packages/oslo_service/wsgi.py", line 143, in _get_socket
TRACE _proxy     sock = eventlet.listen(bind_addr, family, backlog=backlog)
TRACE _proxy   File "/usr/lib/python2.7/site-packages/eventlet/convenience.py", line 47, in listen
TRACE _proxy     sock.listen(backlog)
TRACE _proxy   File "/usr/lib/python2.7/socket.py", line 228, in meth
TRACE _proxy     return getattr(self._sock,name)(*args)
TRACE _proxy error: [Errno 98] Address already in use
TRACE _proxy
```